Workbook
Name Slicer_Year: #N/A

Sheet runs
A3: Row Labels | B3: Sum of Runs
A4: 1 | B4: 1
A5: 2 | B5: 23
A6: 3 | B6: 13
A7: 4 | B7: 12
A8: 5 | B8: 1
A9: 6 | B9: 38
A10: 7 | B10: 34
A11: 8 | B11: 21
A12: 9 | B12: 3
A13: 10 | B13: 10
A14: 11 | B14: 9
A15: 12 | B15: 0
A16: Grand Total | B16: 165

Sheet runs&ball
A3: Row Labels | B3: Sum of Runs | C3: Sum of Balls
A4: 1 | B4: 1 | C4: 5
A5: 2 | B5: 23 | C5: 14
A6: 3 | B6: 13 | C6: 14
A7: 4 | B7: 12 | C7: 7
A8: 5 | B8: 1 | C8: 1
A9: 6 | B9: 38 | C9: 29
A10: 7 | B10: 34 | C10: 36
A11: 8 | B11: 21 | C11: 22
A12: 9 | B12: 3 | C12: 7
A13: 10 | B13: 10 | C13: 16
A14: 11 | B14: 9 | C14: 5
A15: 12 | B15: 0 | C15: 1
A16: Grand Total | B16: 165 | C16: 157

Sheet dotball
A3: Row Labels | B3: Sum of Dot Balls
A4: 1 | B4: 4
A5: 2 | B5: 10
A6: 3 | B6: 13
A7: 4 | B7: 5
A8: 5 | B8: 0
A9: 6 | B9: 26
A10: 7 | B10: 31
A11: 8 | B11: 18
A12: 9 | B12: 7
A13: 10 | B13: 15
A14: 11 | B14: 3
A15: 12 | B15: 1
A16: Grand Total | B16: 133

Sheet innings&runsagainstOpenenets
A3: Row Labels | B3: Sum of Runs
A4: CSK | B4: 22
A5: DCH | B5: 47
A6: DD | B6: 1
A7: KKR | B7: 1
A8: KXIP | B8: 55
A9: MI | B9: 23
A10: RR | B10: 16
A11: Grand Total | B11: 165

Sheet battingAvg
A3: Row Labels | B3: Average of Batting Average
A4: 1 | B4: 1
A5: 2 | B5: 12
A6: 3 | B6: 12.33
A7: 4 | B7: 12.25
A8: 5 | B8: 12.4
A9: 6 | B9: 14.33
A10: 7 | B10: 13.33
A11: 8 | B11: 12.5
A12: 9 | B12: 11.75
A13: 10 | B13: 11.64
A14: 11 | B14: 11.8
A15: 12 | B15: 11.64
A16: Grand Total | B16: 11.414167

Sheet StrikeRate
A3: Row Labels | B3: Sum of Runs | C3: Sum of Balls | D3: Average of SR
A4: 1 | B4: 1 | C4: 5 | D4: 20
A5: 2 | B5: 23 | C5: 14 | D5: 164.29
A6: 3 | B6: 13 | C6: 14 | D6: 92.86
A7: 4 | B7: 12 | C7: 7 | D7: 171.43
A8: 5 | B8: 1 | C8: 1 | D8: 100
A9: 6 | B9: 38 | C9: 29 | D9: 131.03
A10: 7 | B10: 34 | C10: 36 | D10: 94.44
A11: 8 | B11: 21 | C11: 22 | D11: 95.45
A12: 9 | B12: 3 | C12: 7 | D12: 42.86
A13: 10 | B13: 10 | C13: 16 | D13: 62.5
A14: 11 | B14: 9 | C14: 5 | D14: 180
A15: 12 | B15: 0 | C15: 1 | D15: 0
A16: Grand Total | B16: 165 | C16: 157 | D16: 96.238333

Sheet half&century
A3: Row Labels | B3: Sum of 50s | C3: Sum of 100s
A4: 1 | B4: 0 | C4: 0
A5: 2 | B5: 0 | C5: 0
A6: 3 | B6: 0 | C6: 0
A7: 4 | B7: 0 | C7: 0
A8: 5 | B8: 0 | C8: 0
A9: 6 | B9: 0 | C9: 0
A10: 7 | B10: 0 | C10: 0
A11: 8 | B11: 0 | C11: 0
A12: 9 | B12: 0 | C12: 0
A13: 10 | B13: 0 | C13: 0
A14: 11 | B14: 0 | C14: 0
A15: 12 | B15: 0 | C15: 0
A16: Grand Total | B16: 0 | C16: 0

Sheet Four&Six
A3: Row Labels | B3: Sum of 4s | C3: Sum of 6s
A4: 1 | B4: 0 | C4: 0
A5: 2 | B5: 3 | C5: 1
A6: 3 | B6: 0 | C6: 1
A7: 4 | B7: 2 | C7: 0
A8: 5 | B8: 0 | C8: 0
A9: 6 | B9: 1 | C9: 2
A10: 7 | B10: 5 | C10: 0
A11: 8 | B11: 4 | C11: 0
A12: 9 | B12: 0 | C12: 0
A13: 10 | B13: 1 | C13: 0
A14: 11 | B14: 2 | C14: 0
A15: 12 | B15: 0 | C15: 0
A16: Grand Total | B16: 18 | C16: 4

Sheet 2008
A1: S NO. | B1: Year | C1: Opponent | D1: Runs | E1: Balls | F1: 4s | G1: 6s | H1: SR | I1: Dot Balls | J1: 50s | K1: 100s | L1: Out/Not Out | M1: Batting Average
A2: 1 | B2: 2008 | C2: KKR | D2: 1 | E2: 5 | F2: 0 | G2: 0 | H2: 20 | I2: 4 | J2: 0 | K2: 0 | L2: Out | M2: 1
A3: 2 | B3: 2008 | C3: MI | D3: 23 | E3: 14 | F3: 3 | G3: 1 | H3: 164.29 | I3: 10 | J3: 0 | K3: 0 | L3: Out | M3: 12
A4: 3 | B4: 2008 | C4: RR | D4: 13 | E4: 14 | F4: 0 | G4: 1 | H4: 92.86 | I4: 13 | J4: 0 | K4: 0 | L4: Out | M4: 12.33
A5: 4 | B5: 2008 | C5: CSK | D5: 12 | E5: 7 | F5: 2 | G5: 0 | H5: 171.43 | I5: 5 | J5: 0 | K5: 0 | L5: Out | M5: 12.25
A6: 5 | B6: 2008 | C6: DD | D6: 1 | E6: 1 | F6: 0 | G6: 0 | H6: 100 | I6: 0 | J6: 0 | K6: 0 | L6: Not Out | M6: 12.4
A7: 6 | B7: 2008 | C7: DCH | D7: 38 | E7: 29 | F7: 1 | G7: 2 | H7: 131.03 | I7: 26 | J7: 0 | K7: 0 | L7: Out | M7: 14.33
A8: 7 | B8: 2008 | C8: KXIP | D8: 34 | E8: 36 | F8: 5 | G8: 0 | H8: 94.44 | I8: 31 | J8: 0 | K8: 0 | L8: Out | M8: 13.33
A9: 8 | B9: 2008 | C9: KXIP | D9: 21 | E9: 22 | F9: 4 | G9: 0 | H9: 95.45 | I9: 18 | J9: 0 | K9: 0 | L9: Out | M9: 12.5
A10: 9 | B10: 2008 | C10: RR | D10: 3 | E10: 7 | F10: 0 | G10: 0 | H10: 42.86 | I10: 7 | J10: 0 | K10: 0 | L10: Out | M10: 11.75
A11: 10 | B11: 2008 | C11: CSK | D11: 10 | E11: 16 | F11: 1 | G11: 0 | H11: 62.5 | I11: 15 | J11: 0 | K11: 0 | L11: Out | M11: 11.64
A12: 11 | B12: 2008 | C12: DCH | D12: 9 | E12: 5 | F12: 2 | G12: 0 | H12: 180 | I12: 3 | J12: 0 | K12: 0 | L12: Out | M12: 11.8
A13: 12 | B13: 2008 | C13: MI | D13: 0 | E13: 1 | F13: 0 | G13: 0 | H13: 0 | I13: 1 | J13: 0 | K13: 0 | L13: Out | M13: 11.64
C17: Strike Rate | D17: =SUM(D2:D13)/SUM(E2:E13)*100 -> 105.09554 | L17: Avg | M17: =M13 -> 11.64

Sheet 2009
A1: S NO. | B1: Year | C1: Opponent | D1: Runs | E1: Balls | F1: 4s | G1: 6s | H1: SR | I1: Dot Balls | J1: 50s | K1: 100s | L1: Out/Not Out | M1: Batting Average
A2: 1 | B2: 2009 | C2: RR | D2: 3 | E2: 8 | F2: 0 | G2: 0 | H2: 37.5 | I2: 5 | J2: 0 | K2: 0 | L2: out | M2: 3
A3: 2 | B3: 2009 | C3: CSK | D3: 11 | E3: 13 | F3: 0 | G3: 1 | H3: 84.62 | I3: 7 | J3: 0 | K3: 0 | L3: out | M3: 7
A4: 3 | B4: 2009 | C4: DCH | D4: 50 | E4: 32 | F4: 7 | G4: 0 | H4: 156.25 | I4: 10 | J4: 1 | K4: 0 | L4: out | M4: 21.33
A5: 4 | B5: 2009 | C5: KXIP | D5: 2 | E5: 3 | F5: 0 | G5: 0 | H5: 66.77 | I5: 0 | J5: 0 | K5: 0 | L5: out | M5: 16.5
A6: 5 | B6: 2009 | C6: DD | D6: 22 | E6: 24 | F6: 1 | G6: 0 | H6: 91.67 | I6: 7 | J6: 0 | K6: 0 | L6: out | M6: 17.6
A7: 6 | B7: 2009 | C7: KKR | D7: 19 | E7: 12 | F7: 1 | G7: 1 | H7: 158.33 | I7: 3 | J7: 0 | K7: 0 | L7: out | M7: 17.83
A8: 7 | B8: 2009 | C8: KXIP | D8: 16 | E8: 14 | F8: 2 | G8: 0 | H8: 114.29 | I8: 5 | J8: 0 | K8: 0 | L8: out | M8: 17.57
A9: 8 | B9: 2009 | C9: RR | D9: 15 | E9: 22 | F9: 1 | G9: 0 | H9: 68.18 | I9: 12 | J9: 0 | K9: 0 | L9: out | M9: 17.25
A10: 9 | B10: 2009 | C10: MI | D10: 20 | E10: 22 | F10: 4 | G10: 0 | H10: 90.91 | I10: 13 | J10: 0 | K10: 0 | L10: out | M10: 17.56
A11: 10 | B11: 2009 | C11: CSK | D11: 38 | E11: 35 | F11: 4 | G11: 2 | H11: 108.57 | I11: 20 | J11: 0 | K11: 0 | L11: out | M11: 19.6
A12: 11 | B12: 2009 | C12: DCH | D12: 19 | E12: 9 | F12: 0 | G12: 2 | H12: 211.11 | I12: 2 | J12: 0 | K12: 0 | L12: not out | M12: 21.5
A13: 12 | B13: 2009 | C13: CSK | D13: 24 | E13: 17 | F13: 1 | G13: 2 | H13: 141.18 | I13: 8 | J13: 0 | K13: 0 | L13: not out | M13: 23.9
A14: 13 | B14: 2009 | C14: DCH | D14: 7 | E14: 8 | F14: 1 | G14: 0 | H14: 87.5 | I14: 4 | J14: 0 | K14: 0 | L14: out | M14: 22.66
C17: Strike Rate | D17: =SUM(D2:D14)/SUM(E2:E14)*100 -> 112.32877 | L17: Avg | M17: =M14 -> 22.66

Sheet 2010
A1: S NO. | B1: Match No. | C1: Opponent | D1: Runs | E1: Balls | F1: 4s | G1: 6s | H1: SR | I1: Dot Balls | J1: 50s | K1: 100s | L1: Out/Not Out | M1: Batting Average
A2: 1 | B2: 2010 | C2: KKR | D2: 2 | E2: 5 | F2: 0 | G2: 0 | H2: 40 | I2: 3 | J2: 0 | K2: 0 | L2: Out | M2: 2
A3: 2 | B3: 2010 | C3: KXIP | D3: 16 | E3: 12 | F3: 1 | G3: 1 | H3: 133.33 | I3: 4 | J3: 0 | K3: 0 | L3: Not Out | M3: 18
A4: 3 | B4: 2010 | C4: MI | D4: 17 | E4: 12 | F4: 0 | G4: 2 | H4: 141.67 | I4: 5 | J4: 0 | K4: 0 | L4: Out | M4: 17.5
A5: 4 | B5: 2010 | C5: CSK | D5: 24 | E5: 16 | F5: 2 | G5: 1 | H5: 150 | I5: 3 | J5: 0 | K5: 0 | L5: Out | M5: 19.67
A6: 5 | B6: 2010 | C6: DD | D6: 38 | E6: 23 | F6: 4 | G6: 1 | H6: 165.22 | I6: 2 | J6: 0 | K6: 0 | L6: Not Out | M6: 32.33
A7: 6 | B7: 2010 | C7: CSK | D7: 34 | E7: 24 | F7: 3 | G7: 1 | H7: 141.67 | I7: 4 | J7: 0 | K7: 0 | L7: Out | M7: 32.75
A8: 7 | B8: 2010 | C8: KXIP | D8: 42 | E8: 26 | F8: 4 | G8: 1 | H8: 161.54 | I8: 1 | J8: 0 | K8: 0 | L8: Out | M8: 34.6
A9: 8 | B9: 2010 | C9: DD | D9: 13 | E9: 11 | F9: 1 | G9: 0 | H9: 118.18 | I9: 1 | J9: 0 | K9: 0 | L9: Out | M9: 31
A10: 9 | B10: 2010 | C10: DCH | D10: 58 | E10: 35 | F10: 4 | G10: 4 | H10: 165.71 | I10: 9 | J10: 0 | K10: 0 | L10: Out | M10: 34.86
A11: 10 | B11: 2010 | C11: KKR | D11: 0 | E11: 0 | F11: 0 | G11: 0 | H11: – | I11: 0 | J11: 0 | K11: 0 | L11: Not Out | M11: 34.86
A12: 11 | B12: 2010 | C12: DCH | D12: 3 | E12: 4 | F12: 0 | G12: 0 | H12: 75 | I12: 1 | J12: 0 | K12: 0 | L12: Out | M12: 34.86
A13: 12 | B13: 2010 | C13: RR | D13: 14 | E13: 13 | F13: 2 | G13: 0 | H13: – | I13: 6 | J13: 0 | K13: 0 | L13: Out | M13: 34.86
A14: 13 | B14: 2010 | C14: MI | D14: 37 | E14: 24 | F14: 4 | G14: 1 | H14: 154.17 | I14: 4 | J14: 0 | K14: 0 | L14: Out | M14: 35.13
A15: 14 | B15: 2010 | C15: Mi | D15: 9 | E15: 7 | F15: 1 | G15: 0 | H15: 128.57 | I15: 1 | J15: 0 | K15: 0 | L15: Out | M15: 32.22
A16: 15 | B16: 2010 | C16: DCH | D16: 0 | E16: 0 | F16: 0 | G16: 0 | H16: – | I16: 0 | J16: 0 | K16: 0 | L16: Not Out | M16: 32.22
C19: Strike Rate | D19: =SUM(D2:D16)/SUM(E2:E16)*100 -> 144.81132 | L19: Avg | M19: =M16 -> 32.22

Sheet 2011
A1: S NO. | B1: Match No. | C1: Opponent | D1: Runs | E1: Balls | F1: 4s | G1: 6s | H1: SR | I1: Dot Balls | J1: 50s | K1: 100s | L1: Out/Not Out | M1: Batting Average
A2: 1 | B2: 3rd | C2: KTK | D2: 23 | E2: 18 | F2: 4 | G2: 0 | H2: 127.78 | I2: 7 | J2: 0 | K2: 0 | L2: Out | M2: 23
A3: 2 | B3: 8th | C3: MI | D3: 12 | E3: 19 | F3: 2 | G3: 0 | H3: 63.16 | I3: 13 | J3: 0 | K3: 0 | L3: Out | M3: 17.5
A4: 3 | B4: 11th | C4: DCH | D4: 71 | E4: 51 | F4: 5 | G4: 3 | H4: 139.22 | I4: 10 | J4: 1 | K4: 0 | L4: Out | M4: 35.33
A5: 4 | B5: 14th | C5: CSK | D5: 35 | E5: 28 | F5: 4 | G5: 1 | H5: 125 | I5: 11 | J5: 0 | K5: 0 | L5: Out | M5: 35.25
A6: 5 | B6: 24th | C6: KKR | D6: 30 | E6: 23 | F6: 3 | G6: 1 | H6: 130.43 | I6: 8 | J6: 0 | K6: 0 | L6: Not Out | M6: 42.75
A7: 6 | B7: 30th | C7: DD | D7: 56 | E7: 38 | F7: 8 | G7: 2 | H7: 147.36 | I7: 18 | J7: 1 | K7: 0 | L7: Out | M7: 45.4
A8: 7 | B8: 35th | C8: PWI | D8: 67 | E8: 42 | F8: 4 | G8: 4 | H8: 159.52 | I8: 11 | J8: 1 | K8: 0 | L8: Out | M8: 49
A9: 8 | B9: 47th | C9: KXIP | D9: 27 | E9: 31 | F9: 4 | G9: 0 | H9: 87.1 | I9: 16 | J9: 0 | K9: 0 | L9: Out | M9: 45.86
A10: 9 | B10: 50th | C10: KTK | D10: 27 | E10: 33 | F10: 3 | G10: 0 | H10: 81.82 | I10: 15 | J10: 0 | K10: 0 | L10: Not Out | M10: 49.71
A11: 10 | B11: 55th | C11: RR | D11: 39 | E11: 34 | F11: 3 | G11: 0 | H11: 114.71 | I11: 4 | J11: 0 | K11: 0 | L11: Not Out | M11: 55.29
A12: 11 | B12: 58th | C12: KKR | D12: 15 | E12: 15 | F12: 1 | G12: 0 | H12: 100 | I12: 3 | J12: 0 | K12: 0 | L12: Out | M12: 55.56
A13: 12 | B13: 63rd | C13: KXIP | D13: 11 | E13: 11 | F13: 2 | G13: 0 | H13: 100 | I13: 6 | J13: 0 | K13: 0 | L13: Out | M13: 51.1
... A17: 16 | B17: Final | C17: CSK | D17: 35 | E17: 32 | F17: 1 | G17: 1 | H17: 109.38 | I17: 6 | J17: 0 | K17: 0 | L17: Out | M17: 55.56
C20: Strike Rate | D20: =SUM(D2:D17)/SUM(E2:E17)*100 -> 121.08696 | L20: Avg | M20: =M17 -> 55.56

Sheet 2012
A1: S No. | B1: Match No. | C1: Opponent | D1: Runs | E1: Balls | F1: 4s | G1: 6s | H1: SR | I1: Dot Balls | J1: 50s | K1: 100s | L1: Out/Not Out | M1: Batting Avg
A2: 1 | B2: 2012 | C2: DD | D2: 8 | E2: 8 | F2: 1 | G2: 0 | H2: 100 | I2: 4 | J2: 0 | K2: 0 | L2: Out | M2: 28
A3: 2 | B3: 2012 | C3: KKR | D3: 6 | E3: 14 | F3: 0 | G3: 0 | H3: 42.85 | I3: 9 | J3: 0 | K3: 0 | L3: Out | M3: 28
A4: 3 | B4: 2012 | C4: CSK | D4: 57 | E4: 46 | F4: 5 | G4: 2 | H4: 123.91 | I4: 17 | J4: 1 | K4: 0 | L4: Out | M4: 28
A5: 4 | B5: 2012 | C5: RR | D5: 22 | E5: 18 | F5: 1 | G5: 0 | H5: 122.22 | I5: 3 | J5: 0 | K5: 0 | L5: Out | M5: 28
A6: 5 | B6: 2012 | C6: PWI | D6: 16 | E6: 19 | F6: 1 | G6: 0 | H6: 84.21 | I6: 7 | J6: 0 | K6: 0 | L6: Out | M6: 28
A7: 6 | B7: 2012 | C7: KXIP | D7: 4 | E7: 4 | F7: 1 | G7: 0 | H7: 100 | I7: 2 | J7: 0 | K7: 0 | L7: Out | M7: 28
A8: 7 | B8: 2012 | C8: RR | D8: 22 | E8: 18 | F8: 0 | G8: 0 | H8: 122.22 | I8: 1 | J8: 0 | K8: 0 | L8: Out | M8: 28
A9: 8 | B9: 2012 | C9: KKR | D9: 18 | E9: 19 | F9: 3 | G9: 0 | H9: 94.74 | I9: 9 | J9: 0 | K9: 0 | L9: Out | M9: 28
A10: 9 | B10: 2012 | C10: KXIP | D10: 45 | E10: 42 | F10: 3 | G10: 2 | H10: 107.14 | I10: 11 | J10: 0 | K10: 0 | L10: Out | M10: 28
A11: 10 | B11: 2012 | C11: DCH | D11: 9 | E11: 9 | F11: 1 | G11: 0 | H11: 100 | I11: 3 | J11: 0 | K11: 0 | L11: Out | M11: 28
A12: 11 | B12: 2012 | C12: MI | D12: 36 | E12: 25 | F12: 1 | G12: 2 | H12: 144 | I12: 3 | J12: 0 | K12: 0 | L12: Not Out | M12: 28
A13: 12 | B13: 2012 | C13: PWI | D13: 9 | E13: 12 | F13: 1 | G13: 0 | H13: 75 | I13: 5 | J13: 0 | K13: 0 | L13: Out | M13: 28
... A16: 15 | B16: 2012 | C16: DCH | D16: 42 | E16: 40 | F16: 2 | G16: 2 | H16: 105 | I16: 15 | J16: 0 | K16: 0 | L16: Out | M16: 28
C19: Strike Rate | D19: =SUM(D2:D16)/SUM(E2:E16)*100 -> 110.97561 | L19: Avg | M19: =M16 -> 28

Sheet 2013
A1: S NO. | B1: Match No. | C1: Opponent | D1: Runs | E1: Balls | F1: 4s | G1: 6s | H1: SR | I1: Dot Balls | J1: 50s | K1: 100s | L1: Out/Not Out | M1: Batting Average
A2: 1 | B2: 2013 | C2: MI | D2: 24 | E2: 14 | F2: 4 | G2: 1 | H2: 171.43 | I2: 4 | J2: 0 | K2: 0 | L2: Out | M2: 24
A3: 2 | B3: 2013 | C3: SRH | D3: 46 | E3: 44 | F3: 5 | G3: 1 | H3: 104.55 | I3: 22 | J3: 0 | K3: 0 | L3: Out | M3: 35
A4: 3 | B4: 2013 | C4: SRH | D4: 93 | E4: 47 | F4: 11 | G4: 4 | H4: 197.87 | I4: 10 | J4: 1 | K4: 0 | L4: not out | M4: 81.5
A5: 4 | B5: 2013 | C5: KKR | D5: 35 | E5: 27 | F5: 4 | G5: 2 | H5: 129.63 | I5: 17 | J5: 0 | K5: 0 | L5: out | M5: 66
A6: 5 | B6: 2013 | C6: CSK | D6: 58 | E6: 47 | F6: 2 | G6: 2 | H6: 123.4 | I6: 5 | J6: 1 | K6: 0 | L6: out | M6: 64
A7: 6 | B7: 2013 | C7: DD | D7: 65 | E7: 50 | F7: 7 | G7: 1 | H7: 130 | I7: 15 | J7: 1 | K7: 0 | L7: out | M7: 64.2
A8: 7 | B8: 2013 | C8: RR | D8: 1 | E8: 4 | F8: 0 | G8: 0 | H8: 25 | I8: 2 | J8: 0 | K8: 0 | L8: out | M8: 53.67
A9: 8 | B9: 2013 | C9: PWI | D9: 11 | E9: 9 | F9: 0 | G9: 1 | H9: 122.22 | I9: 2 | J9: 0 | K9: 0 | L9: out | M9: 47.57
A10: 9 | B10: 2013 | C10: MI | D10: 1 | E10: 4 | F10: 0 | G10: 0 | H10: 25 | I10: 2 | J10: 0 | K10: 0 | L10: out | M10: 41.75
A11: 10 | B11: 2013 | C11: RR | D11: 32 | E11: 35 | F11: 3 | G11: 0 | H11: 91.33 | I11: 13 | J11: 0 | K11: 0 | L11: out | M11: 40.67
A12: 11 | B12: 2013 | C12: PWI | D12: 25 | E12: 18 | F12: 3 | G12: 0 | H12: 138.89 | I12: 4 | J12: 0 | K12: 0 | L12: out | M12: 39.1
A13: 12 | B13: 2013 | C13: KXIP | D13: 14 | E13: 14 | F13: 1 | G13: 0 | H13: 100 | I13: 4 | J13: 0 | K13: 0 | L13: out | M13: 36.82
... A17: 16 | B17: 2013 | C17: CSK | D17: 56 | E17: 29 | F17: 6 | G17: 4 | H17: 193.1 | I17: 12 | J17: 1 | K17: 0 | L17: not out | M17: 45.29
C21: Strike Rate | D21: =SUM(D2:D17)/SUM(E2:E17)*100 -> 138.73085 | L21: Avg | M21: =M17 -> 45.29

Sheet 2014
A1: S NO. | B1: Match No. | C1: Opponent | D1: Runs | E1: Balls | F1: 4s | G1: 6s | H1: SR | I1: Dot Balls | J1: 50s | K1: 100s | L1: Out/Not Out | M1: Batting Average
A2: 1 | B2: 2014 | C2: DD | D2: 49 | E2: 38 | F2: 2 | G2: 3 | H2: 128.95 | I2: 10 | J2: 0 | K2: 0 | L2: Not Out | M2: 0
A3: 2 | B3: 2014 | C3: MI | D3: 0 | E3: 2 | F3: 0 | G3: 0 | H3: 0 | I3: 2 | J3: 0 | K3: 0 | L3: Out | M3: 49
A4: 3 | B4: 2014 | C4: KKR | D4: 31 | E4: 23 | F4: 4 | G4: 0 | H4: 134.78 | I4: 4 | J4: 0 | K4: 0 | L4: Out | M4: 40
A5: 4 | B5: 2014 | C5: RR | D5: 21 | E5: 25 | F5: 3 | G5: 0 | H5: 84 | I5: 13 | J5: 0 | K5: 0 | L5: Out | M5: 33.67
A6: 5 | B6: 2014 | C6: KXIP | D6: 4 | E6: 2 | F6: 1 | G6: 0 | H6: 200 | I6: 1 | J6: 0 | K6: 0 | L6: Out | M6: 26.25
A7: 6 | B7: 2014 | C7: SRH | D7: 0 | E7: 5 | F7: 0 | G7: 0 | H7: 0 | I7: 5 | J7: 0 | K7: 0 | L7: Out | M7: 21
A8: 7 | B8: 2014 | C8: MI | D8: 35 | E8: 28 | F8: 2 | G8: 2 | H8: 125 | I8: 9 | J8: 0 | K8: 0 | L8: Out | M8: 23.33
A9: 8 | B9: 2014 | C9: KXIP | D9: 0 | E9: 1 | F9: 0 | G9: 0 | H9: 0 | I9: 1 | J9: 0 | K9: 0 | L9: Out | M9: 20
A10: 9 | B10: 2014 | C10: RR | D10: 4 | E10: 9 | F10: 1 | G10: 0 | H10: 44.44 | I10: 8 | J10: 0 | K10: 0 | L10: Out | M10: 18
A11: 10 | B11: 2014 | C11: DD | D11: 10 | E11: 11 | F11: 0 | G11: 0 | H11: 90.91 | I11: 1 | J11: 0 | K11: 0 | L11: Out | M11: 17.11
A12: 11 | B12: 2014 | C12: CSK | D12: 27 | E12: 29 | F12: 1 | G12: 1 | H12: 93.1 | I12: 10 | J12: 0 | K12: 0 | L12: Out | M12: 18.1
A13: 12 | B13: 2014 | C13: SRH | D13: 67 | E13: 41 | F13: 4 | G13: 4 | H13: 163.41 | I13: 6 | J13: 1 | K13: 0 | L13: Out | M13: 22.55
... A15: 14 | B15: 2014 | C15: CSK | D15: 73 | E15: 49 | F15: 2 | G15: 5 | H15: 148.98 | I15: 7 | J15: 1 | K15: 0 | L15: Out | M15: 27.62
C18: Strike Rate | D18: =SUM(D2:D15)/SUM(E2:E15)*100 -> 122.10884 | L18: Avg | M18: =M15 -> 27.62

Sheet 2015
A1: S NO. | B1: Match No. | C1: Opponent | D1: Runs | E1: Balls | F1: 4s | G1: 6s | H1: SR | I1: Dot Balls | J1: 50s | K1: 100s | L1: Out/Not Out | M1: Batting Average
A2: 1 | B2: 2015 | C2: KKR | D2: 13 | E2: 15 | F2: 0 | G2: 1 | H2: 86.67 | I2: 2 | J2: 0 | K2: 0 | L2: Out | M2: 13
A3: 2 | B3: 2015 | C3: SRH | D3: 41 | E3: 37 | F3: 4 | G3: 2 | H3: 110.81 | I3: 5 | J3: 0 | K3: 0 | L3: Out | M3: 27
A4: 3 | B4: 2015 | C4: MI | D4: 18 | E4: 18 | F4: 1 | G4: 1 | H4: 100 | I4: 0 | J4: 0 | K4: 0 | L4: Out | M4: 24
A5: 4 | B5: 2015 | C5: CSK | D5: 51 | E5: 42 | F5: 4 | G5: 2 | H5: 121.43 | I5: 12 | J5: 1 | K5: 0 | L5: Out | M5: 30.75
A6: 5 | B6: 2015 | C6: RR | D6: 62 | E6: 46 | F6: 1 | G6: 3 | H6: 134.78 | I6: 6 | J6: 1 | K6: 0 | L6: out | M6: 35
A7: 5 | B7: 2015 | C7: DD | D7: 35 | E7: 23 | F7: 6 | G7: 0 | H7: 152.17 | I7: 5 | J7: 0 | K7: 0 | L7: Not Out | M7: 39.5
A8: 6 | B8: 2015 | C8: RR | D8: 1 | E8: 4 | F8: 0 | G8: 0 | H8: 25 | I8: 2 | J8: 0 | K8: 0 | L8: Out | M8: 31.8
A9: 7 | B9: 2015 | C9: KKR | D9: 34 | E9: 20 | F9: 2 | G9: 3 | H9: 170 | I9: 7 | J9: 0 | K9: 0 | L9: Out | M9: 32.17
A10: 8 | B10: 2015 | C10: CSK | D10: 48 | E10: 44 | F10: 2 | G10: 1 | H10: 109.09 | I10: 6 | J10: 0 | K10: 0 | L10: Out | M10: 34.43
A11: 9 | B11: 2015 | C11: KXIP | D11: 32 | E11: 30 | F11: 3 | G11: 1 | H11: 106.67 | I11: 12 | J11: 0 | K11: 0 | L11: Out | M11: 34.13
A12: 10 | B12: 2015 | C12: MI | D12: 82 | E12: 50 | F12: 6 | G12: 4 | H12: 164 | I12: 8 | J12: 1 | K12: 0 | L12: Not Out | M12: 44.38
A13: 11 | B13: 2015 | C13: KXIP | D13: 19 | E13: 9 | F13: 2 | G13: 1 | H13: 211.11 | I13: 1 | J13: 0 | K13: 0 | L13: Out | M13: 41.56
... A17: 15 | B17: 2015 | C17: CSK | D17: 12 | E17: 9 | F17: 1 | G17: 1 | H17: 133.33 | I17: 6 | J17: 0 | K17: 0 | L17: out | M17: 38
C20: Strike Rate | D20: =SUM(D2:D17)/SUM(E2:E17)*100 -> 130.82902 | L20: Avg | M20: =M17 -> 38

Sheet 2016
A1: S NO. | B1: Match No. | C1: Opponent | D1: Runs | E1: Balls | F1: 4s | G1: 6s | H1: SR | I1: Dot Balls | J1: 50s | K1: 100s | L1: Out/NotOt | M1: Batting Average
A2: 1 | B2: 2016 | C2: SRH | D2: 75 | E2: 51 | F2: 7 | G2: 3 | H2: 147.06 | I2: 17 | J2: 1 | K2: 0 | L2: Out | M2: 75
A3: 2 | B3: 2016 | C3: DD | D3: 79 | E3: 48 | F3: 7 | G3: 3 | H3: 164.58 | I3: 8 | J3: 1 | K3: 0 | L3: Out | M3: 77
A4: 3 | B4: 2016 | C4: MI | D4: 33 | E4: 30 | F4: 3 | G4: 0 | H4: 110 | I4: 9 | J4: 0 | K4: 0 | L4: Out | M4: 62.33
A5: 4 | B5: 2016 | C5: RPSG | D5: 80 | E5: 63 | F5: 7 | G5: 2 | H5: 126.98 | I5: 17 | J5: 1 | K5: 0 | L5: Out | M5: 66.75
A6: 5 | B6: 2016 | C6: GL | D6: 100 | E6: 63 | F6: 11 | G6: 1 | H6: 158.73 | I6: 11 | J6: 0 | K6: 1 | L6: Not Out | M6: 91.75
A7: 6 | B7: 2016 | C7: SRH | D7: 14 | E7: 17 | F7: 1 | G7: 0 | H7: 82.35 | I7: 6 | J7: 0 | K7: 0 | L7: Out | M7: 76.2
A8: 7 | B8: 2016 | C8: KKR | D8: 52 | E8: 44 | F8: 4 | G8: 0 | H8: 118.18 | I8: 10 | J8: 1 | K8: 0 | L8: Out | M8: 72.17
A9: 8 | B9: 2016 | C9: RPSG | D9: 108 | E9: 58 | F9: 8 | G9: 7 | H9: 186.21 | I9: 13 | J9: 0 | K9: 1 | L9: Not Out | M9: 90.17
A10: 9 | B10: 2016 | C10: KXIP | D10: 20 | E10: 21 | F10: 2 | G10: 0 | H10: 95.24 | I10: 9 | J10: 0 | K10: 0 | L10: Out | M10: 80.14
A11: 10 | B11: 2016 | C11: MI | D11: 7 | E11: 7 | F11: 0 | G11: 1 | H11: 100 | I11: 5 | J11: 0 | K11: 0 | L11: Out | M11: 71
A12: 11 | B12: 2016 | C12: GL | D12: 109 | E12: 55 | F12: 6 | G12: 8 | H12: 198.18 | I12: 11 | J12: 0 | K12: 1 | L12: Out | M12: 75.22
A13: 12 | B13: 2016 | C13: KKR | D13: 75 | E13: 51 | F13: 5 | G13: 3 | H13: 147.06 | I13: 13 | J13: 1 | K13: 0 | L13: Not Out | M13: 83.56
... A17: 16 | B17: 2016 | C17: SRH | D17: 54 | E17: 35 | F17: 5 | G17: 2 | H17: 154.29 | I17: 11 | J17: 1 | K17: 0 | L17: Out | M17: 81.08
C21: Strike Rate | D21: =SUM(D2:D17)/SUM(E2:E17)*100 -> 152.03125 | L21: Avg | M21: =M17 -> 81.08

Sheet 2017
A1: S No. | B1: Match No. | C1: Opponent | D1: Runs | E1: Balls | F1: 4s | G1: 6s | H1: SR | I1: Dot Balls | J1: 50s | K1: 100s | L1: Out/Not Out | M1: Batting Average
A2: 1 | B2: 2017 | C2: MI | D2: 62 | E2: 47 | F2: 5 | G2: 2 | H2: 131.91 | I2: 14 | J2: 1 | K2: 0 | L2: Out | M2: 62
A3: 2 | B3: 2017 | C3: RPSG | D3: 28 | E3: 19 | F3: 3 | G3: 1 | H3: 147.37 | I3: 6 | J3: 0 | K3: 0 | L3: Out | M3: 45
A4: 3 | B4: 2017 | C4: GL | D4: 64 | E4: 50 | F4: 7 | G4: 1 | H4: 128 | I4: 16 | J4: 1 | K4: 0 | L4: Out | M4: 51.33
A5: 4 | B5: 2017 | C5: KKR | D5: 0 | E5: 1 | F5: 0 | G5: 0 | H5: 0 | I5: 0 | J5: 0 | K5: 0 | L5: Out | M5: 38.5
A6: 5 | B6: 2017 | C6: GL | D6: 10 | E6: 13 | F6: 0 | G6: 1 | H6: 76.92 | I6: 8 | J6: 0 | K6: 0 | L6: Out | M6: 32.8
A7: 6 | B7: 2017 | C7: RPSG | D7: 55 | E7: 48 | F7: 4 | G7: 1 | H7: 114.58 | I7: 7 | J7: 1 | K7: 0 | L7: Out | M7: 36.5
A8: 7 | B8: 2017 | C8: MI | D8: 20 | E8: 14 | F8: 0 | G8: 2 | H8: 142.86 | I8: 5 | J8: 0 | K8: 0 | L8: Out | M8: 34.14
A9: 8 | B9: 2017 | C9: KXIP | D9: 6 | E9: 6 | F9: 1 | G9: 0 | H9: 100 | I9: 2 | J9: 0 | K9: 0 | L9: Out | M9: 30.63
A10: 9 | B10: 2017 | C10: KKR | D10: 5 | E10: 9 | F10: 0 | G10: 0 | H10: 55.56 | I10: 4 | J10: 0 | K10: 0 | L10: Out | M10: 27.78
A11: 10 | B11: 2017 | C11: DD | D11: 58 | E11: 45 | F11: 3 | G11: 3 | H11: 128.89 | I11: 7 | J11: 1 | K11: 0 | L11: Out | M11: 30.8
C15: Strike Rate | D15: =SUM(D2:D11)/SUM(E2:E11)*100 -> 122.22222 | L15: Avg | M15: =M11 -> 30.8

Sheet 2018
A1: S NO. | B1: Match No. | C1: Opponent | D1: Runs | E1: Balls | F1: 4s | G1: 6s | H1: SR | I1: Dot Balls | J1: 50s | K1: 100s | L1: Out/Not Out | M1: Batting Average
A2: 1 | B2: 2018 | C2: KKR | D2: 31 | E2: 33 | F2: 1 | G2: 1 | H2: 93.94 | I2: 10 | J2: 0 | K2: 0 | L2: Out | M2: 31
A3: 2 | B3: 2018 | C3: KXIP | D3: 21 | E3: 16 | F3: 4 | G3: 0 | H3: 131.25 | I3: 7 | J3: 0 | K3: 0 | L3: Out | M3: 26
A4: 3 | B4: 2018 | C4: RR | D4: 57 | E4: 30 | F4: 6 | G4: 2 | H4: 190 | I4: 1 | J4: 1 | K4: 0 | L4: Out | M4: 36.33
A5: 4 | B5: 2018 | C5: MI | D5: 92 | E5: 62 | F5: 7 | G5: 4 | H5: 148.38 | I5: 11 | J5: 1 | K5: 0 | L5: Not Out | M5: 67
A6: 5 | B6: 2018 | C6: DD | D6: 30 | E6: 26 | F6: 2 | G6: 1 | H6: 115.38 | I6: 7 | J6: 0 | K6: 0 | L6: Out | M6: 57.75
A7: 6 | B7: 2018 | C7: CSK | D7: 18 | E7: 15 | F7: 3 | G7: 0 | H7: 120 | I7: 6 | J7: 0 | K7: 0 | L7: Out | M7: 49.8
A8: 7 | B8: 2018 | C8: KKR | D8: 68 | E8: 44 | F8: 5 | G8: 3 | H8: 154.54 | I8: 6 | J8: 1 | K8: 0 | L8: Not Out | M8: 63.4
A9: 8 | B9: 2018 | C9: MI | D9: 32 | E9: 26 | F9: 2 | G9: 1 | H9: 123.08 | I9: 5 | J9: 0 | K9: 0 | L9: Out | M9: 58.17
A10: 9 | B10: 2018 | C10: CSK | D10: 8 | E10: 11 | F10: 1 | G10: 0 | H10: 72.73 | I10: 6 | J10: 0 | K10: 0 | L10: Out | M10: 51
A11: 10 | B11: 2018 | C11: SRH | D11: 39 | E11: 30 | F11: 5 | G11: 1 | H11: 130 | I11: 11 | J11: 0 | K11: 0 | L11: Out | M11: 49.5
A12: 11 | B12: 2018 | C12: DD | D12: 70 | E12: 40 | F12: 7 | G12: 3 | H12: 175 | I12: 6 | J12: 1 | K12: 0 | L12: Out | M12: 51.78
A13: 12 | B13: 2018 | C13: KXIP | D13: 48 | E13: 28 | F13: 6 | G13: 2 | H13: 171.43 | I13: 8 | J13: 1 | K13: 0 | L13: Not Out | M13: 57.11
... A15: 14 | B15: 2018 | C15: RR | D15: 4 | E15: 9 | F15: 0 | G15: 0 | H15: 44.44 | I15: 5 | J15: 0 | K15: 0 | L15: Out | M15: 48.18
C18: Strike Rate | D18: =SUM(D2:D15)/SUM(E2:E15)*100 -> 139.10761 | L18: Avg | M18: =M15 -> 48.18

Sheet 2019
A1: S NO. | B1: Match No. | C1: Opponent | D1: Runs | E1: Balls | F1: 4s | G1: 6s | H1: SR (strike rate) | I1: Dot Balls | J1: 50s | K1: 100s | L1: Out/Not Out | M1: Batting Average
A2: 1 | B2: 2019 | C2: CSK | D2: 6 | E2: 12 | F2: 0 | G2: 0 | H2: 50 | I2: 6 | J2: 0 | K2: 0 | L2: Out | M2: 6
A3: 2 | B3: 2019 | C3: MI | D3: 46 | E3: 32 | F3: 6 | G3: 0 | H3: 143.75 | I3: 4 | J3: 0 | K3: 0 | L3: Out | M3: 26
A4: 3 | B4: 2019 | C4: SRH | D4: 3 | E4: 10 | F4: 0 | G4: 0 | H4: 30 | I4: 7 | J4: 0 | K4: 0 | L4: Out | M4: 18.33
A5: 4 | B5: 2019 | C5: RR | D5: 23 | E5: 25 | F5: 3 | G5: 0 | H5: 92 | I5: 11 | J5: 0 | K5: 0 | L5: Out | M5: 19.5
A6: 5 | B6: 2019 | C6: KKR | D6: 84 | E6: 49 | F6: 9 | G6: 2 | H6: 171.43 | I6: 2 | J6: 1 | K6: 0 | L6: Out | M6: 32.4
A7: 6 | B7: 2019 | C7: DD | D7: 41 | E7: 33 | F7: 1 | G7: 2 | H7: 124.24 | I7: 5 | J7: 0 | K7: 0 | L7: Out | M7: 33.83
A8: 7 | B8: 2019 | C8: KXIP | D8: 67 | E8: 53 | F8: 8 | G8: 0 | H8: 126.42 | I8: 10 | J8: 1 | K8: 0 | L8: Out | M8: 38.57
A9: 8 | B9: 2019 | C9: MI | D9: 8 | E9: 9 | F9: 1 | G9: 0 | H9: 88.89 | I9: 4 | J9: 0 | K9: 0 | L9: Out | M9: 34.75
A10: 9 | B10: 2019 | C10: KKR | D10: 100 | E10: 58 | F10: 9 | G10: 4 | H10: 172.41 | I10: 5 | J10: 1 | K10: 1 | L10: Out | M10: 42
A11: 10 | B11: 2019 | C11: CSK | D11: 9 | E11: 8 | F11: 2 | G11: 0 | H11: 112.5 | I11: 5 | J11: 0 | K11: 0 | L11: Out | M11: 38.7
A12: 11 | B12: 2019 | C12: KXIP | D12: 13 | E12: 8 | F12: 2 | G12: 0 | H12: 162.5 | I12: 1 | J12: 0 | K12: 0 | L12: Out | M12: 36.36
A13: 12 | B13: 2019 | C13: DD | D13: 23 | E13: 17 | F13: 2 | G13: 1 | H13: 135.29 | I13: 5 | J13: 0 | K13: 0 | L13: Out | M13: 35.25
... A15: 14 | B15: 2019 | C15: SRH | D15: 16 | E15: 7 | F15: 2 | G15: 1 | H15: 228.57 | I15: 2 | J15: 0 | K15: 0 | L15: Out | M15: 33.14
C18: Strike Rate | D18: =SUM(D2:D15)/SUM(E2:E15)*100 -> 141.46341 | L18: Avg | M18: =M15 -> 33.14

Sheet 2020
A1: S NO. | B1: Match No. | C1: Opponent | D1: Runs | E1: Balls | F1: 4s | G1: 6s | H1: SR | I1: Dot Balls | J1: 50s | K1: 100s | L1: Out/Not Out | M1: Batting Average
A2: 1 | B2: 2020 | C2: SRH | D2: 14 | E2: 13 | F2: 0 | G2: 0 | H2: 107.69 | I2: 2 | J2: 0 | K2: 0 | L2: Out | M2: 14
A3: 2 | B3: 2020 | C3: KXIP | D3: 1 | E3: 5 | F3: 0 | G3: 0 | H3: 20 | I3: 4 | J3: 0 | K3: 0 | L3: Out | M3: 7.5
A4: 3 | B4: 2020 | C4: MI | D4: 3 | E4: 11 | F4: 0 | G4: 0 | H4: 27.27 | I4: 8 | J4: 0 | K4: 0 | L4: Out | M4: 6
A5: 4 | B5: 2020 | C5: RR | D5: 72 | E5: 53 | F5: 7 | G5: 2 | H5: 135.85 | I5: 19 | J5: 1 | K5: 0 | L5: Not Out | M5: 30
A6: 5 | B6: 2020 | C6: DD | D6: 43 | E6: 39 | F6: 2 | G6: 1 | H6: 110.26 | I6: 12 | J6: 0 | K6: 0 | L6: Out | M6: 33.25
A7: 6 | B7: 2020 | C7: CSK | D7: 90 | E7: 52 | F7: 4 | G7: 4 | H7: 173.08 | I7: 5 | J7: 1 | K7: 0 | L7: Not Out | M7: 55.75
A8: 7 | B8: 2020 | C8: KKR | D8: 33 | E8: 28 | F8: 1 | G8: 0 | H8: 117.86 | I8: 5 | J8: 0 | K8: 0 | L8: Not Out | M8: 64
A9: 8 | B9: 2020 | C9: KXIP | D9: 48 | E9: 39 | F9: 3 | G9: 0 | H9: 123.08 | I9: 5 | J9: 0 | K9: 0 | L9: Out | M9: 60.8
A10: 9 | B10: 2020 | C10: RR | D10: 43 | E10: 32 | F10: 1 | G10: 2 | H10: 134.38 | I10: 8 | J10: 0 | K10: 0 | L10: Out | M10: 57.83
A11: 10 | B11: 2020 | C11: KKR | D11: 18 | E11: 17 | F11: 2 | G11: 0 | H11: 105.88 | I11: 6 | J11: 0 | K11: 0 | L11: Not Out | M11: 60.83
A12: 11 | B12: 2020 | C12: CSK | D12: 50 | E12: 43 | F12: 1 | G12: 1 | H12: 116.28 | I12: 7 | J12: 1 | K12: 0 | L12: Out | M12: 59.29
A13: 12 | B13: 2020 | C13: MI | D13: 9 | E13: 14 | F13: 0 | G13: 0 | H13: 64.29 | I13: 7 | J13: 0 | K13: 0 | L13: Out | M13: 53
... A16: 15 | B16: 2020 | C16: SRH | D16: 6 | E16: 7 | F16: 0 | G16: 0 | H16: 85.71 | I16: 3 | J16: 0 | K16: 0 | L16: Out | M16: 42.36
C19: Strike Rate | D19: =SUM(D2:D16)/SUM(E2:E16)*100 -> 121.35417 | L19: Avg | M19: =M16 -> 42.36

Sheet 2021
A1: S NO. | B1: Match No. | C1: Opponent | D1: Runs | E1: Balls | F1: 4s | G1: 6s | H1: SR | I1: Dot Balls | J1: 50s | K1: 100s | L1: Out/Not Out | M1: Batting Average
A2: 1 | B2: 2021 | C2: MI | D2: 33 | E2: 29 | F2: 4 | G2: 0 | H2: 113.79 | I2: 15 | J2: 0 | K2: 0 | L2: Out | M2: 33
A3: 2 | B3: 2021 | C3: SRH | D3: 33 | E3: 29 | F3: 4 | G3: 0 | H3: 113.79 | I3: 15 | J3: 0 | K3: 0 | L3: Out | M3: 33
A4: 3 | B4: 2021 | C4: KKR | D4: 5 | E4: 6 | F4: 1 | G4: 0 | H4: 83.33 | I4: 4 | J4: 0 | K4: 0 | L4: Out | M4: 23.67
A5: 4 | B5: 2021 | C5: RR | D5: 72 | E5: 47 | F5: 6 | G5: 3 | H5: 153.19 | I5: 8 | J5: 1 | K5: 0 | L5: Not Out | M5: 47.67
A6: 5 | B6: 2021 | C6: CSK | D6: 8 | E6: 7 | F6: 1 | G6: 0 | H6: 114.29 | I6: 2 | J6: 0 | K6: 0 | L6: Out | M6: 37.75
A7: 6 | B7: 2021 | C7: DD | D7: 12 | E7: 11 | F7: 2 | G7: 0 | H7: 109.09 | I7: 5 | J7: 0 | K7: 0 | L7: Out | M7: 32.6
A8: 7 | B8: 2021 | C8: KXIP | D8: 35 | E8: 3 | F8: 0 | G8: 0 | H8: 0 | I8: 3 | J8: 0 | K8: 0 | L8: Out | M8: 27.17
A9: 8 | B9: 2021 | C9: KKR | D9: 5 | E9: 4 | F9: 1 | G9: 0 | H9: 125 | I9: 2 | J9: 0 | K9: 0 | L9: Out | M9: 24
A10: 9 | B10: 2021 | C10: CSK | D10: 53 | E10: 41 | F10: 6 | G10: 1 | H10: 129.27 | I10: 11 | J10: 1 | K10: 0 | L10: Out | M10: 27.62
A11: 10 | B11: 2021 | C11: MI | D11: 51 | E11: 42 | F11: 3 | G11: 3 | H11: 121.43 | I11: 12 | J11: 1 | K11: 0 | L11: Out | M11: 30.22
A12: 11 | B12: 2021 | C12: RR | D12: 25 | E12: 20 | F12: 4 | G12: 0 | H12: 125 | I12: 7 | J12: 0 | K12: 0 | L12: Out | M12: 32.5
A13: 12 | B13: 2021 | C13: KXIP | D13: 25 | E13: 24 | F13: 2 | G13: 1 | H13: 104.17 | I13: 12 | J13: 0 | K13: 0 | L13: Out | M13: 31.82
... A16: 15 | B16: 2021 | C16: KKR | D16: 39 | E16: 20 | F16: 2 | G16: 2 | H16: 194 | I16: 7 | J16: 0 | K16: 0 | L16: Out | M16: 28.92
C19: Strike Rate | D19: =SUM(D2:D16)/SUM(E2:E16)*100 -> 137.28814 | L19: Avg | M19: =M16 -> 28.92

Sheet 2022
A1: S No. | B1: Match No. | C1: Opponent | D1: Runs | E1: Balls | F1: 4s | G1: 6s | H1: SR | I1: Dot Balls | J1: 50s | K1: 100s | L1: Out/Not Out | M1: Batting AVG
A2: 1 | B2: 2022 | C2: KXIP | D2: 41 | E2: 29 | F2: 1 | G2: 2 | H2: 141.38 | I2: 8 | J2: 0 | K2: 0 | L2: Not Out | M2: 41
A3: 2 | B3: 2022 | C3: KKR | D3: 12 | E3: 7 | F3: 2 | G3: 0 | H3: 171.43 | I3: 5 | J3: 0 | K3: 0 | L3: Out | M3: 53
A4: 3 | B4: 2022 | C4: RR | D4: 5 | E4: 6 | F4: 0 | G4: 0 | H4: 83.33 | I4: 3 | J4: 0 | K4: 0 | L4: Out | M4: 29
A5: 4 | B5: 2022 | C5: MI | D5: 48 | E5: 36 | F5: 5 | G5: 0 | H5: 133.33 | I5: 4 | J5: 0 | K5: 0 | L5: Out | M5: 35.33
A6: 5 | B6: 2022 | C6: CSK | D6: 1 | E6: 3 | F6: 0 | G6: 0 | H6: 33.33 | I6: 1 | J6: 0 | K6: 0 | L6: Out | M6: 26.75
A7: 6 | B7: 2022 | C7: DD | D7: 12 | E7: 14 | F7: 1 | G7: 0 | H7: 85.71 | I7: 5 | J7: 0 | K7: 0 | L7: Out | M7: 23.8
A8: 7 | B8: 2022 | C8: LSG | D8: 0 | E8: 1 | F8: 0 | G8: 0 | H8: 0 | I8: 0 | J8: 0 | K8: 0 | L8: Out | M8: 19.83
A9: 8 | B9: 2022 | C9: SRH | D9: 0 | E9: 1 | F9: 0 | G9: 0 | H9: 0 | I9: 0 | J9: 0 | K9: 0 | L9: Out | M9: 17
A10: 9 | B10: 2022 | C10: RR | D10: 9 | E10: 10 | F10: 2 | G10: 0 | H10: 90 | I10: 7 | J10: 0 | K10: 0 | L10: Out | M10: 16
A11: 10 | B11: 2022 | C11: GT | D11: 58 | E11: 53 | F11: 6 | G11: 1 | H11: 109.43 | I11: 7 | J11: 1 | K11: 0 | L11: Out | M11: 20.67
A12: 11 | B12: 2022 | C12: CSK | D12: 30 | E12: 33 | F12: 3 | G12: 1 | H12: 90.91 | I12: 8 | J12: 0 | K12: 0 | L12: Out | M12: 21.6
A13: 12 | B13: 2022 | C13: SRH | D13: 0 | E13: 1 | F13: 0 | G13: 0 | H13: 0 | I13: 0 | J13: 0 | K13: 0 | L13: Out | M13: 19.64
... A17: 16 | B17: 2022 | C17: RR | D17: 7 | E17: 8 | F17: 0 | G17: 1 | H17: 87.5 | I17: 5 | J17: 0 | K17: 0 | L17: Out | M17: 22.73
C20: Strike Rate | D20: =SUM(D2:D17)/SUM(E2:E17)*100 -> 115.98639 | L20: Avg | M20: =M17 -> 22.73

Sheet 2023
A1: S NO. | B1: Match No. | C1: Opponent | D1: Runs | E1: Balls | F1: 4s | G1: 6s | H1: SR | I1: Dot Balls | J1: 50s | K1: 100s | L1: Out/Not Out | M1: Batting Average
A2: 1 | B2: 2023 | C2: MI | D2: 82 | E2: 49 | F2: 6 | G2: 5 | H2: 167.35 | I2: 15 | J2: 1 | K2: 0 | L2: Not Out | M2: 0
A3: 2 | B3: 2023 | C3: KKR | D3: 21 | E3: 18 | F3: 3 | G3: 0 | H3: 116.67 | I3: 9 | J3: 0 | K3: 0 | L3: Out | M3: 82
A4: 3 | B4: 2023 | C4: LSG | D4: 61 | E4: 44 | F4: 4 | G4: 4 | H4: 138.64 | I4: 16 | J4: 1 | K4: 0 | L4: Out | M4: 54.33
A5: 4 | B5: 2023 | C5: DD | D5: 50 | E5: 34 | F5: 6 | G5: 1 | H5: 147.06 | I5: 9 | J5: 1 | K5: 0 | L5: Out | M5: 54.33
A6: 5 | B6: 2023 | C6: CSK | D6: 6 | E6: 4 | F6: 1 | G6: 0 | H6: 150 | I6: 2 | J6: 0 | K6: 0 | L6: Out | M6: 44.75
A7: 6 | B7: 2023 | C7: KXIP | D7: 59 | E7: 47 | F7: 5 | G7: 1 | H7: 125.53 | I7: 13 | J7: 1 | K7: 0 | L7: Out | M7: 44.43
A8: 7 | B8: 2023 | C8: RR | D8: 0 | E8: 1 | F8: 0 | G8: 0 | H8: 0 | I8: 1 | J8: 0 | K8: 0 | L8: Out | M8: 40.86
A9: 8 | B9: 2023 | C9: KKR | D9: 54 | E9: 37 | F9: 6 | G9: 0 | H9: 145.95 | I9: 5 | J9: 1 | K9: 0 | L9: Out | M9: 41.13
A10: 9 | B10: 2023 | C10: LSG | D10: 31 | E10: 30 | F10: 3 | G10: 0 | H10: 103.33 | I10: 9 | J10: 0 | K10: 0 | L10: Out | M10: 40
A11: 10 | B11: 2023 | C11: DD | D11: 55 | E11: 46 | F11: 5 | G11: 0 | H11: 119.57 | I11: 12 | J11: 1 | K11: 0 | L11: Out | M11: 40.31
A12: 11 | B12: 2023 | C12: MI | D12: 1 | E12: 4 | F12: 0 | G12: 0 | H12: 25 | I12: 3 | J12: 0 | K12: 0 | L12: Out | M12: 36.64
A13: 12 | B13: 2023 | C13: RR | D13: 18 | E13: 19 | F13: 1 | G13: 0 | H13: 94.74 | I13: 4 | J13: 0 | K13: 0 | L13: Out | M13: 35.75
... A15: 14 | B15: 2023 | C15: GT | D15: 101 | E15: 61 | F15: 13 | G15: 1 | H15: 165.57 | I15: 10 | J15: 0 | K15: 1 | L15: Not Out | M15: 53.25
C18: Strike Rate | D18: =SUM(D2:D15)/SUM(E2:E15)*100 -> 139.82495 | L18: Avg | M18: =M15 -> 53.25

Sheet 2024
A1: S NO. | B1: Match No. | C1: Opponent | D1: Runs | E1: Balls | F1: 4s | G1: 6s | H1: SR | I1: Dot Balls | J1: 50s | K1: 100s | L1: Out/Not Out | M1: Batting Average
A2: 1 | B2: 2024 | C2: CSK | D2: 21 | E2: 20 | F2: 0 | G2: 1 | H2: 105 | I2: 6 | J2: 0 | K2: 0 | L2: Out | M2: 21
A3: 2 | B3: 2024 | C3: KXIP | D3: 77 | E3: 49 | F3: 11 | G3: 2 | H3: 157.1 | I3: 19 | J3: 1 | K3: 0 | L3: Out | M3: 49
A4: 3 | B4: 2024 | C4: KKR | D4: 83 | E4: 59 | F4: 4 | G4: 4 | H4: 140.7 | I4: 16 | J4: 1 | K4: 0 | L4: Not Out | M4: 80.5
A5: 4 | B5: 2024 | C5: LSG | D5: 22 | E5: 16 | F5: 2 | G5: 1 | H5: 137.5 | I5: 6 | J5: 0 | K5: 0 | L5: Out | M5: 62
A6: 5 | B6: 2024 | C6: RR | D6: 113 | E6: 72 | F6: 12 | G6: 4 | H6: 156.9 | I6: 20 | J6: 0 | K6: 1 | L6: Not Out | M6: 79.5
A7: 6 | B7: 2024 | C7: MI | D7: 3 | E7: 9 | F7: 0 | G7: 0 | H7: 33.3 | I7: 6 | J7: 0 | K7: 0 | L7: Out | M7: 64
A8: 7 | B8: 2024 | C8: SRH | D8: 42 | E8: 20 | F8: 6 | G8: 2 | H8: 210 | I8: 7 | J8: 0 | K8: 0 | L8: Out | M8: 61.86
A9: 8 | B9: 2024 | C9: KKR | D9: 18 | E9: 7 | F9: 1 | G9: 2 | H9: 257.1 | I9: 2 | J9: 0 | K9: 0 | L9: Out | M9: 60.88
A10: 9 | B10: 2024 | C10: SRH | D10: 51 | E10: 43 | F10: 4 | G10: 1 | H10: 118.6 | I10: 11 | J10: 1 | K10: 0 | L10: Out | M10: 60.1
A11: 10 | B11: 2024 | C11: GT | D11: 70 | E11: 44 | F11: 6 | G11: 3 | H11: 159.1 | I11: 10 | J11: 1 | K11: 0 | L11: Not Out | M11: 63.27
A12: 11 | B12: 2024 | C12: GT | D12: 42 | E12: 27 | F12: 2 | G12: 4 | H12: 155.6 | I12: 11 | J12: 0 | K12: 0 | L12: Out | M12: 61.92
A13: 12 | B13: 2024 | C13: KXIP | D13: 92 | E13: 47 | F13: 7 | G13: 6 | H13: 195.7 | I13: 11 | J13: 1 | K13: 0 | L13: Out | M13: 64.36
... A16: 15 | B16: 2024 | C16: RR | D16: 33 | E16: 24 | F16: 3 | G16: 1 | H16: 137.5 | I16: 7 | J16: 0 | K16: 0 | L16: Out | M16: 61.75
C19: Strike Rate | D19: =SUM(D2:D16)/SUM(E2:E16)*100 -> 154.69729 | L19: Avg | M19: =M16 -> 61.75

Sheet 2025
A1: S NO. | B1: Match No. | C1: Opponent | D1: Runs | E1: Balls | F1: 4s | G1: 6s | H1: SR | I1: Dot Balls | J1: 50s | K1: 100s | L1: Out/Not Out | M1: Batting Average
A2: 1 | B2: 2025 | C2: KKR | D2: 59 | E2: 36 | F2: 5 | G2: 1 | H2: 163.89 | I2: 8 | J2: 1 | K2: 0 | L2: Not Out | M2: 59
A3: 2 | B3: 2025 | C3: CSK | D3: 31 | E3: 30 | F3: 2 | G3: 1 | H3: 103.33 | I3: 11 | J3: 0 | K3: 0 | L3: Out | M3: 90
A4: 3 | B4: 2025 | C4: GT | D4: 7 | E4: 6 | F4: 1 | G4: 0 | H4: 116.67 | I4: 2 | J4: 0 | K4: 0 | L4: Out | M4: 48.5
A5: 4 | B5: 2025 | C5: MI | D5: 67 | E5: 42 | F5: 8 | G5: 2 | H5: 159.52 | I5: 11 | J5: 1 | K5: 0 | L5: Out | M5: 54.67
A6: 5 | B6: 2025 | C6: DD | D6: 22 | E6: 14 | F6: 1 | G6: 2 | H6: 157.14 | I6: 2 | J6: 0 | K6: 0 | L6: Out | M6: 46.5
A7: 6 | B7: 2025 | C7: RR | D7: 62 | E7: 45 | F7: 4 | G7: 2 | H7: 137.78 | I7: 13 | J7: 1 | K7: 0 | L7: Not Out | M7: 62
A8: 7 | B8: 2025 | C8: KXIP | D8: 1 | E8: 3 | F8: 0 | G8: 0 | H8: 33.33 | I8: 1 | J8: 0 | K8: 0 | L8: Out | M8: 49.8
A9: 8 | B9: 2025 | C9: KXIP | D9: 73 | E9: 54 | F9: 7 | G9: 1 | H9: 135.19 | I9: 12 | J9: 1 | K9: 0 | L9: Not Out | M9: 64.4
A10: 9 | B10: 2025 | C10: RR | D10: 70 | E10: 42 | F10: 8 | G10: 2 | H10: 166.67 | I10: 10 | J10: 1 | K10: 0 | L10: Out | M10: 65.33
A11: 10 | B11: 2025 | C11: DD | D11: 51 | E11: 47 | F11: 4 | G11: 0 | H11: 108.51 | I11: 14 | J11: 1 | K11: 0 | L11: Out | M11: 63.29
A12: 11 | B12: 2025 | C12: CSK | D12: 62 | E12: 33 | F12: 5 | G12: 5 | H12: 187.88 | I12: 3 | J12: 1 | K12: 0 | L12: Out | M12: 63.12
A13: 12 | B13: 2025 | C13: SRH | D13: 43 | E13: 25 | F13: 7 | G13: 1 | H13: 172 | I13: 6 | J13: 0 | K13: 0 | L13: Out | M13: 60.89
... A16: 15 | B16: 2025 | C16: KXIP | D16: 43 | E16: 35 | F16: 3 | G16: 0 | H16: 122.86 | I16: 9 | J16: 0 | K16: 0 | L16: Out | M16: 54.75
C19: Strike Rate | D19: =SUM(D2:D16)/SUM(E2:E16)*100 -> 144.71366 | L19: Avg | M19: =M16 -> 54.75

Sheet 2008-2025
A1: No of Match | B1: Year | C1: Opponent | D1: Runs | E1: Balls | F1: 4s | G1: 6s | H1: SR | I1: Dot Balls | J1: 50s | K1: 100s | L1: Out/Not Out | M1: Batting Average
A2: 1 | B2: 2008 | C2: KKR | D2: 1 | E2: 5 | F2: 0 | G2: 0 | H2: 20 | I2: 4 | J2: 0 | K2: 0 | L2: Out | M2: 1
A3: 2 | B3: 2008 | C3: MI | D3: 23 | E3: 14 | F3: 3 | G3: 1 | H3: 164.29 | I3: 10 | J3: 0 | K3: 0 | L3: Out | M3: 12
A4: 3 | B4: 2008 | C4: RR | D4: 13 | E4: 14 | F4: 0 | G4: 1 | H4: 92.86 | I4: 13 | J4: 0 | K4: 0 | L4: Out | M4: 12.33
A5: 4 | B5: 2008 | C5: CSK | D5: 12 | E5: 7 | F5: 2 | G5: 0 | H5: 171.43 | I5: 5 | J5: 0 | K5: 0 | L5: Out | M5: 12.25
A6: 5 | B6: 2008 | C6: DD | D6: 1 | E6: 1 | F6: 0 | G6: 0 | H6: 100 | I6: 0 | J6: 0 | K6: 0 | L6: Not Out | M6: 12.4
A7: 6 | B7: 2008 | C7: DCH | D7: 38 | E7: 29 | F7: 1 | G7: 2 | H7: 131.03 | I7: 26 | J7: 0 | K7: 0 | L7: Out | M7: 14.33
A8: 7 | B8: 2008 | C8: KXIP | D8: 34 | E8: 36 | F8: 5 | G8: 0 | H8: 94.44 | I8: 31 | J8: 0 | K8: 0 | L8: Out | M8: 13.33
A9: 8 | B9: 2008 | C9: KXIP | D9: 21 | E9: 22 | F9: 4 | G9: 0 | H9: 95.45 | I9: 18 | J9: 0 | K9: 0 | L9: Out | M9: 12.5
A10: 9 | B10: 2008 | C10: RR | D10: 3 | E10: 7 | F10: 0 | G10: 0 | H10: 42.86 | I10: 7 | J10: 0 | K10: 0 | L10: Out | M10: 11.75
A11: 10 | B11: 2008 | C11: CSK | D11: 10 | E11: 16 | F11: 1 | G11: 0 | H11: 62.5 | I11: 15 | J11: 0 | K11: 0 | L11: Out | M11: 11.64
A12: 11 | B12: 2008 | C12: DCH | D12: 9 | E12: 5 | F12: 2 | G12: 0 | H12: 180 | I12: 3 | J12: 0 | K12: 0 | L12: Out | M12: 11.8
A13: 12 | B13: 2008 | C13: MI | D13: 0 | E13: 1 | F13: 0 | G13: 0 | H13: 0 | I13: 1 | J13: 0 | K13: 0 | L13: Out | M13: 11.64
... A260: 259 | B260: 2025 | C260: KXIP | D260: 43 | E260: 35 | F260: 3 | G260: 0 | H260: 122.86 | I260: 9 | J260: 0 | K260: 0 | L260: Out | M260: 54.75

Sheet KPI'S
A2: 1.No of Innings Played | D2: 2.No of Innings Played Against Opponents | G2: 3.No of Run's Score Against Opponents | J2: 4.Total Runs Year wise | M2: 5.No of 50's Each Year | P2: 6.No of 100's Each Year
A3: Row Labels | B3: No of Innings Played | D3: Row Labels | E3: Count of No of Match | G3: Row Labels | H3: Sum of Runs | J3: Row Labels | K3: Sum of Runs | M3: Row Labels | N3: Sum of 50s | P3: Row Labels | Q3: Sum of 100s
A4: 2016 | B4: 16 | D4: DD | E4: 2 | G4: DD | H4: 133 | J4: 2016 | K4: 973 | M4: 2016 | N4: 7 | P4: 2016 | Q4: 4
A5: Grand Total | B5: 16 | D5: GL | E5: 3 | G5: GL | H5: 209 | J5: Grand Total | K5: 973 | M5: Grand Total | N5: 7 | P5: Grand Total | Q5: 4
D6: KKR | E6: 2 | G6: KKR | H6: 127
D7: KXIP | E7: 2 | G7: KXIP | H7: 133
D8: MI | E8: 2 | G8: MI | H8: 40
D9: RPSG | E9: 2 | G9: RPSG | H9: 188
D10: SRH | E10: 3 | G10: SRH | H10: 143
D11: Grand Total | E11: 16 | G11: Grand Total | H11: 973
A26: 7.No of Four Score Each Year | D26: 8.No of Six Score Each Year | G26: 9.No of Bowls & Dot's Bowl Played Each Year | K26: 10. No of Times Out & Not Out Each Year | N26: 11. Batting Strike Rate Year Wise | Q26: 12.Batting AVG Each Year
A27: Row Labels | B27: Sum of 4s | D27: Row Labels | E27: Sum of 6s | G27: Row Labels | H27: Sum of Balls | I27: Sum of Dot Balls | K27: Row Labels | L27: Count of Out/Not Out | N27: Year | O27: Strike Rate | Q27: Year | R27: Batting AVG
A28: 2016 | B28: 84 | D28: 2016 | E28: 38 | G28: 2016 | H28: 640 | I28: 169 | K28: Not Out | L28: 4 | N28: 2008 | O28: ='2008'!D17 -> 105.09554 | Q28: 2008 | R28: ='2008'!M17 -> 11.64
A29: Grand Total | B29: 84 | D29: Grand Total | E29: 38 | G29: Grand Total | H29: 640 | I29: 169 | K29: 2016 | L29: 4 | N29: 2009 | O29: ='2009'!D17 -> 112.32877 | Q29: 2009 | R29: ='2009'!M17 -> 22.66
K30: Out | L30: 12 | N30: 2010 | O30: ='2010'!D19 -> 144.81132 | Q30: 2010 | R30: ='2010'!M19 -> 32.22
K31: 2016 | L31: 12 | N31: 2011 | O31: ='2011'!D20 -> 121.08696 | Q31: 2011 | R31: ='2011'!M20 -> 55.56
K32: Grand Total | L32: 16 | N32: 2012 | O32: ='2012'!D19 -> 110.97561 | Q32: 2012 | R32: ='2012'!M19 -> 28
N33: 2013 | O33: ='2013'!D21 -> 138.73085 | Q33: 2013 | R33: ='2013'!M21 -> 45.29
N34: 2014 | O34: ='2014'!D18 -> 122.10884 | Q34: 2014 | R34: ='2014'!M18 -> 27.62
N35: 2015 | O35: ='2015'!D20 -> 130.82902 | Q35: 2015 | R35: ='2015'!M20 -> 38
N36: 2016 | O36: ='2016'!D21 -> 152.03125 | Q36: 2016 | R36: ='2016'!M21 -> 81.08
N37: 2017 | O37: ='2017'!D15 -> 122.22222 | Q37: 2017 | R37: ='2017'!M15 -> 30.8
N38: 2018 | O38: ='2018'!D18 -> 139.10761 | Q38: 2018 | R38: ='2018'!M18 -> 48.18
N39: 2019 | O39: ='2019'!D18 -> 141.46341 | Q39: 2019 | R39: ='2019'!M18 -> 33.14
N40: 2020 | O40: ='2020'!D19 -> 121.35417 | Q40: 2020 | R40: ='2020'!M19 -> 42.36
N41: 2021 | O41: ='2021'!D19 -> 137.28814 | Q41: 2021 | R41: ='2021'!M19 -> 28.92
N42: 2022 | O42: ='2022'!D20 -> 115.98639 | Q42: 2022 | R42: ='2022'!M20 -> 22.73
N43: 2023 | O43: ='2023'!D18 -> 139.82495 | Q43: 2023 | R43: ='2023'!M18 -> 53.25
N44: 2024 | O44: ='2024'!D19 -> 154.69729 | Q44: 2024 | R44: ='2024'!M19 -> 61.75
N45: 2025 | O45: ='2025'!D19 -> 144.71366 | Q45: 2025 | R45: ='2025'!M19 -> 54.75
N46: Grand Total | O46: ='2008-2025'!D263 -> 0 | Q46: Grand Total | R46: ='2008-2025'!M263 -> 0
C56: Row Labels | D56: Average of Strike Rate | G56: Row Labels | H56: Average of Batting AVG
C57: 2008 | D57: 105.09554 | G57: 2008 | H57: 11.64
C58: 2009 | D58: 112.32877 | G58: 2009 | H58: 22.66
C59: 2010 | D59: 144.81132 | G59: 2010 | H59: 32.22
C60: 2011 | D60: 121.08696 | G60: 2011 | H60: 55.56
C61: 2012 | D61: 110.97561 | G61: 2012 | H61: 28
C62: 2013 | D62: 138.73085 | G62: 2013 | H62: 45.29
C63: 2014 | D63: 122.10884 | G63: 2014 | H63: 27.62
C64: 2015 | D64: 130.82902 | G64: 2015 | H64: 38
...

Sheet Dashboard
